Traceback (most recent call last):
  File "run.py", line 9, in <module>
    http_server.serve_forever()
  File "/Users/olasteen/GoogleDrive/Kandidatprojekt/sentiment-web/venv/lib/python2.7/site-packages/gevent/baseserver.py", line 360, in serve_forever
    self.start()
  File "/Users/olasteen/GoogleDrive/Kandidatprojekt/sentiment-web/venv/lib/python2.7/site-packages/gevent/baseserver.py", line 304, in start
    self.init_socket()
  File "/Users/olasteen/GoogleDrive/Kandidatprojekt/sentiment-web/venv/lib/python2.7/site-packages/gevent/pywsgi.py", line 1451, in init_socket
    StreamServer.init_socket(self)
  File "/Users/olasteen/GoogleDrive/Kandidatprojekt/sentiment-web/venv/lib/python2.7/site-packages/gevent/server.py", line 127, in init_socket
    self.socket = self.get_listener(self.address, self.backlog, self.family)
  File "/Users/olasteen/GoogleDrive/Kandidatprojekt/sentiment-web/venv/lib/python2.7/site-packages/gevent/server.py", line 138, in get_listener
    return _tcp_listener(address, backlog=backlog, reuse_addr=cls.reuse_addr, family=family)
  File "/Users/olasteen/GoogleDrive/Kandidatprojekt/sentiment-web/venv/lib/python2.7/site-packages/gevent/server.py", line 228, in _tcp_listener
    sock.bind(address)
  File "<string>", line 1, in bind
socket.error: [Errno 13] Permission denied: ('', 80)
Traceback (most recent call last):
  File "run.py", line 9, in <module>
    http_server.serve_forever()
  File "/Users/olasteen/GoogleDrive/Kandidatprojekt/sentiment-web/venv/lib/python2.7/site-packages/gevent/baseserver.py", line 360, in serve_forever
    self.start()
  File "/Users/olasteen/GoogleDrive/Kandidatprojekt/sentiment-web/venv/lib/python2.7/site-packages/gevent/baseserver.py", line 304, in start
    self.init_socket()
  File "/Users/olasteen/GoogleDrive/Kandidatprojekt/sentiment-web/venv/lib/python2.7/site-packages/gevent/pywsgi.py", line 1451, in init_socket
    StreamServer.init_socket(self)
  File "/Users/olasteen/GoogleDrive/Kandidatprojekt/sentiment-web/venv/lib/python2.7/site-packages/gevent/server.py", line 127, in init_socket
    self.socket = self.get_listener(self.address, self.backlog, self.family)
  File "/Users/olasteen/GoogleDrive/Kandidatprojekt/sentiment-web/venv/lib/python2.7/site-packages/gevent/server.py", line 138, in get_listener
    return _tcp_listener(address, backlog=backlog, reuse_addr=cls.reuse_addr, family=family)
  File "/Users/olasteen/GoogleDrive/Kandidatprojekt/sentiment-web/venv/lib/python2.7/site-packages/gevent/server.py", line 228, in _tcp_listener
    sock.bind(address)
  File "<string>", line 1, in bind
socket.error: [Errno 13] Permission denied: ('', 80)
Traceback (most recent call last):
  File "run.py", line 9, in <module>
    http_server.serve_forever()
  File "/Users/olasteen/GoogleDrive/Kandidatprojekt/sentiment-web/venv/lib/python2.7/site-packages/gevent/baseserver.py", line 360, in serve_forever
    self.start()
  File "/Users/olasteen/GoogleDrive/Kandidatprojekt/sentiment-web/venv/lib/python2.7/site-packages/gevent/baseserver.py", line 304, in start
    self.init_socket()
  File "/Users/olasteen/GoogleDrive/Kandidatprojekt/sentiment-web/venv/lib/python2.7/site-packages/gevent/pywsgi.py", line 1451, in init_socket
    StreamServer.init_socket(self)
  File "/Users/olasteen/GoogleDrive/Kandidatprojekt/sentiment-web/venv/lib/python2.7/site-packages/gevent/server.py", line 127, in init_socket
    self.socket = self.get_listener(self.address, self.backlog, self.family)
  File "/Users/olasteen/GoogleDrive/Kandidatprojekt/sentiment-web/venv/lib/python2.7/site-packages/gevent/server.py", line 138, in get_listener
    return _tcp_listener(address, backlog=backlog, reuse_addr=cls.reuse_addr, family=family)
  File "/Users/olasteen/GoogleDrive/Kandidatprojekt/sentiment-web/venv/lib/python2.7/site-packages/gevent/server.py", line 228, in _tcp_listener
    sock.bind(address)
  File "<string>", line 1, in bind
socket.error: [Errno 13] Permission denied: ('', 80)
Traceback (most recent call last):
  File "run.py", line 9, in <module>
    http_server.serve_forever()
  File "/Users/olasteen/GoogleDrive/Kandidatprojekt/sentiment-web/venv/lib/python2.7/site-packages/gevent/baseserver.py", line 360, in serve_forever
    self.start()
  File "/Users/olasteen/GoogleDrive/Kandidatprojekt/sentiment-web/venv/lib/python2.7/site-packages/gevent/baseserver.py", line 304, in start
    self.init_socket()
  File "/Users/olasteen/GoogleDrive/Kandidatprojekt/sentiment-web/venv/lib/python2.7/site-packages/gevent/pywsgi.py", line 1451, in init_socket
    StreamServer.init_socket(self)
  File "/Users/olasteen/GoogleDrive/Kandidatprojekt/sentiment-web/venv/lib/python2.7/site-packages/gevent/server.py", line 127, in init_socket
    self.socket = self.get_listener(self.address, self.backlog, self.family)
  File "/Users/olasteen/GoogleDrive/Kandidatprojekt/sentiment-web/venv/lib/python2.7/site-packages/gevent/server.py", line 138, in get_listener
    return _tcp_listener(address, backlog=backlog, reuse_addr=cls.reuse_addr, family=family)
  File "/Users/olasteen/GoogleDrive/Kandidatprojekt/sentiment-web/venv/lib/python2.7/site-packages/gevent/server.py", line 228, in _tcp_listener
    sock.bind(address)
  File "<string>", line 1, in bind
socket.error: [Errno 13] Permission denied: ('', 80)
Traceback (most recent call last):
  File "run.py", line 9, in <module>
    http_server.serve_forever()
  File "/Users/olasteen/GoogleDrive/Kandidatprojekt/sentiment-web/venv/lib/python2.7/site-packages/gevent/baseserver.py", line 360, in serve_forever
    self.start()
  File "/Users/olasteen/GoogleDrive/Kandidatprojekt/sentiment-web/venv/lib/python2.7/site-packages/gevent/baseserver.py", line 304, in start
    self.init_socket()
  File "/Users/olasteen/GoogleDrive/Kandidatprojekt/sentiment-web/venv/lib/python2.7/site-packages/gevent/pywsgi.py", line 1451, in init_socket
    StreamServer.init_socket(self)
  File "/Users/olasteen/GoogleDrive/Kandidatprojekt/sentiment-web/venv/lib/python2.7/site-packages/gevent/server.py", line 127, in init_socket
    self.socket = self.get_listener(self.address, self.backlog, self.family)
  File "/Users/olasteen/GoogleDrive/Kandidatprojekt/sentiment-web/venv/lib/python2.7/site-packages/gevent/server.py", line 138, in get_listener
    return _tcp_listener(address, backlog=backlog, reuse_addr=cls.reuse_addr, family=family)
  File "/Users/olasteen/GoogleDrive/Kandidatprojekt/sentiment-web/venv/lib/python2.7/site-packages/gevent/server.py", line 228, in _tcp_listener
    sock.bind(address)
  File "<string>", line 1, in bind
socket.error: [Errno 13] Permission denied: ('', 80)
Traceback (most recent call last):
  File "run.py", line 9, in <module>
    http_server.serve_forever()
  File "/Users/olasteen/GoogleDrive/Kandidatprojekt/sentiment-web/venv/lib/python2.7/site-packages/gevent/baseserver.py", line 360, in serve_forever
    self.start()
  File "/Users/olasteen/GoogleDrive/Kandidatprojekt/sentiment-web/venv/lib/python2.7/site-packages/gevent/baseserver.py", line 304, in start
    self.init_socket()
  File "/Users/olasteen/GoogleDrive/Kandidatprojekt/sentiment-web/venv/lib/python2.7/site-packages/gevent/pywsgi.py", line 1451, in init_socket
    StreamServer.init_socket(self)
  File "/Users/olasteen/GoogleDrive/Kandidatprojekt/sentiment-web/venv/lib/python2.7/site-packages/gevent/server.py", line 127, in init_socket
    self.socket = self.get_listener(self.address, self.backlog, self.family)
  File "/Users/olasteen/GoogleDrive/Kandidatprojekt/sentiment-web/venv/lib/python2.7/site-packages/gevent/server.py", line 138, in get_listener
    return _tcp_listener(address, backlog=backlog, reuse_addr=cls.reuse_addr, family=family)
  File "/Users/olasteen/GoogleDrive/Kandidatprojekt/sentiment-web/venv/lib/python2.7/site-packages/gevent/server.py", line 228, in _tcp_listener
    sock.bind(address)
  File "<string>", line 1, in bind
socket.error: [Errno 48] Address already in use: ('', 3000)
[2017-02-28 13:32:26,484] ERROR in app: Exception on / [GET]
Traceback (most recent call last):
  File "/Users/olasteen/GoogleDrive/Kandidatprojekt/sentiment-web/venv/lib/python2.7/site-packages/flask/app.py", line 1982, in wsgi_app
    response = self.full_dispatch_request()
  File "/Users/olasteen/GoogleDrive/Kandidatprojekt/sentiment-web/venv/lib/python2.7/site-packages/flask/app.py", line 1614, in full_dispatch_request
    rv = self.handle_user_exception(e)
  File "/Users/olasteen/GoogleDrive/Kandidatprojekt/sentiment-web/venv/lib/python2.7/site-packages/flask/app.py", line 1517, in handle_user_exception
    reraise(exc_type, exc_value, tb)
  File "/Users/olasteen/GoogleDrive/Kandidatprojekt/sentiment-web/venv/lib/python2.7/site-packages/flask/app.py", line 1612, in full_dispatch_request
    rv = self.dispatch_request()
  File "/Users/olasteen/GoogleDrive/Kandidatprojekt/sentiment-web/venv/lib/python2.7/site-packages/flask/app.py", line 1598, in dispatch_request
    return self.view_functions[rule.endpoint](**req.view_args)
  File "/Users/olasteen/GoogleDrive/Kandidatprojekt/sentiment-web/server.py", line 32, in home
    conn.incr(STATS_KEY + "_hits")
  File "/Users/olasteen/GoogleDrive/Kandidatprojekt/sentiment-web/venv/lib/python2.7/site-packages/redis/client.py", line 915, in incr
    return self.execute_command('INCRBY', name, amount)
  File "/Users/olasteen/GoogleDrive/Kandidatprojekt/sentiment-web/venv/lib/python2.7/site-packages/redis/client.py", line 578, in execute_command
    connection.send_command(*args)
  File "/Users/olasteen/GoogleDrive/Kandidatprojekt/sentiment-web/venv/lib/python2.7/site-packages/redis/connection.py", line 563, in send_command
    self.send_packed_command(self.pack_command(*args))
  File "/Users/olasteen/GoogleDrive/Kandidatprojekt/sentiment-web/venv/lib/python2.7/site-packages/redis/connection.py", line 538, in send_packed_command
    self.connect()
  File "/Users/olasteen/GoogleDrive/Kandidatprojekt/sentiment-web/venv/lib/python2.7/site-packages/redis/connection.py", line 442, in connect
    raise ConnectionError(self._error_message(e))
ConnectionError: Error 61 connecting to :6379. Connection refused.
::1 - - [2017-02-28 13:32:26] "GET / HTTP/1.1" 500 412 0.002254
[2017-02-28 13:32:33,681] ERROR in app: Exception on / [GET]
Traceback (most recent call last):
  File "/Users/olasteen/GoogleDrive/Kandidatprojekt/sentiment-web/venv/lib/python2.7/site-packages/flask/app.py", line 1982, in wsgi_app
    response = self.full_dispatch_request()
  File "/Users/olasteen/GoogleDrive/Kandidatprojekt/sentiment-web/venv/lib/python2.7/site-packages/flask/app.py", line 1614, in full_dispatch_request
    rv = self.handle_user_exception(e)
  File "/Users/olasteen/GoogleDrive/Kandidatprojekt/sentiment-web/venv/lib/python2.7/site-packages/flask/app.py", line 1517, in handle_user_exception
    reraise(exc_type, exc_value, tb)
  File "/Users/olasteen/GoogleDrive/Kandidatprojekt/sentiment-web/venv/lib/python2.7/site-packages/flask/app.py", line 1612, in full_dispatch_request
    rv = self.dispatch_request()
  File "/Users/olasteen/GoogleDrive/Kandidatprojekt/sentiment-web/venv/lib/python2.7/site-packages/flask/app.py", line 1598, in dispatch_request
    return self.view_functions[rule.endpoint](**req.view_args)
  File "/Users/olasteen/GoogleDrive/Kandidatprojekt/sentiment-web/server.py", line 32, in home
    conn.incr(STATS_KEY + "_hits")
  File "/Users/olasteen/GoogleDrive/Kandidatprojekt/sentiment-web/venv/lib/python2.7/site-packages/redis/client.py", line 915, in incr
    return self.execute_command('INCRBY', name, amount)
  File "/Users/olasteen/GoogleDrive/Kandidatprojekt/sentiment-web/venv/lib/python2.7/site-packages/redis/client.py", line 578, in execute_command
    connection.send_command(*args)
  File "/Users/olasteen/GoogleDrive/Kandidatprojekt/sentiment-web/venv/lib/python2.7/site-packages/redis/connection.py", line 563, in send_command
    self.send_packed_command(self.pack_command(*args))
  File "/Users/olasteen/GoogleDrive/Kandidatprojekt/sentiment-web/venv/lib/python2.7/site-packages/redis/connection.py", line 538, in send_packed_command
    self.connect()
  File "/Users/olasteen/GoogleDrive/Kandidatprojekt/sentiment-web/venv/lib/python2.7/site-packages/redis/connection.py", line 442, in connect
    raise ConnectionError(self._error_message(e))
ConnectionError: Error 61 connecting to :6379. Connection refused.
::1 - - [2017-02-28 13:32:33] "GET / HTTP/1.1" 500 412 0.023207
::1 - - [2017-02-28 13:32:33] "GET /favicon.ico HTTP/1.1" 404 342 0.020531
[2017-02-28 13:32:42,620] ERROR in app: Exception on / [GET]
Traceback (most recent call last):
  File "/Users/olasteen/GoogleDrive/Kandidatprojekt/sentiment-web/venv/lib/python2.7/site-packages/flask/app.py", line 1982, in wsgi_app
    response = self.full_dispatch_request()
  File "/Users/olasteen/GoogleDrive/Kandidatprojekt/sentiment-web/venv/lib/python2.7/site-packages/flask/app.py", line 1614, in full_dispatch_request
    rv = self.handle_user_exception(e)
  File "/Users/olasteen/GoogleDrive/Kandidatprojekt/sentiment-web/venv/lib/python2.7/site-packages/flask/app.py", line 1517, in handle_user_exception
    reraise(exc_type, exc_value, tb)
  File "/Users/olasteen/GoogleDrive/Kandidatprojekt/sentiment-web/venv/lib/python2.7/site-packages/flask/app.py", line 1612, in full_dispatch_request
    rv = self.dispatch_request()
  File "/Users/olasteen/GoogleDrive/Kandidatprojekt/sentiment-web/venv/lib/python2.7/site-packages/flask/app.py", line 1598, in dispatch_request
    return self.view_functions[rule.endpoint](**req.view_args)
  File "/Users/olasteen/GoogleDrive/Kandidatprojekt/sentiment-web/server.py", line 32, in home
    conn.incr(STATS_KEY + "_hits")
  File "/Users/olasteen/GoogleDrive/Kandidatprojekt/sentiment-web/venv/lib/python2.7/site-packages/redis/client.py", line 915, in incr
    return self.execute_command('INCRBY', name, amount)
  File "/Users/olasteen/GoogleDrive/Kandidatprojekt/sentiment-web/venv/lib/python2.7/site-packages/redis/client.py", line 578, in execute_command
    connection.send_command(*args)
  File "/Users/olasteen/GoogleDrive/Kandidatprojekt/sentiment-web/venv/lib/python2.7/site-packages/redis/connection.py", line 563, in send_command
    self.send_packed_command(self.pack_command(*args))
  File "/Users/olasteen/GoogleDrive/Kandidatprojekt/sentiment-web/venv/lib/python2.7/site-packages/redis/connection.py", line 538, in send_packed_command
    self.connect()
  File "/Users/olasteen/GoogleDrive/Kandidatprojekt/sentiment-web/venv/lib/python2.7/site-packages/redis/connection.py", line 442, in connect
    raise ConnectionError(self._error_message(e))
ConnectionError: Error 61 connecting to :6379. Connection refused.
::1 - - [2017-02-28 13:32:42] "GET / HTTP/1.1" 500 412 0.002630
Traceback (most recent call last):
  File "run.py", line 9, in <module>
    http_server.serve_forever()
  File "/Users/olasteen/GoogleDrive/Kandidatprojekt/sentiment-web/venv/lib/python2.7/site-packages/gevent/baseserver.py", line 360, in serve_forever
    self.start()
  File "/Users/olasteen/GoogleDrive/Kandidatprojekt/sentiment-web/venv/lib/python2.7/site-packages/gevent/baseserver.py", line 304, in start
    self.init_socket()
  File "/Users/olasteen/GoogleDrive/Kandidatprojekt/sentiment-web/venv/lib/python2.7/site-packages/gevent/pywsgi.py", line 1451, in init_socket
    StreamServer.init_socket(self)
  File "/Users/olasteen/GoogleDrive/Kandidatprojekt/sentiment-web/venv/lib/python2.7/site-packages/gevent/server.py", line 127, in init_socket
    self.socket = self.get_listener(self.address, self.backlog, self.family)
  File "/Users/olasteen/GoogleDrive/Kandidatprojekt/sentiment-web/venv/lib/python2.7/site-packages/gevent/server.py", line 138, in get_listener
    return _tcp_listener(address, backlog=backlog, reuse_addr=cls.reuse_addr, family=family)
  File "/Users/olasteen/GoogleDrive/Kandidatprojekt/sentiment-web/venv/lib/python2.7/site-packages/gevent/server.py", line 228, in _tcp_listener
    sock.bind(address)
  File "<string>", line 1, in bind
socket.error: [Errno 48] Address already in use: ('', 5037)
[2017-02-28 13:37:15,056] ERROR in app: Exception on / [GET]
Traceback (most recent call last):
  File "/Users/olasteen/GoogleDrive/Kandidatprojekt/sentiment-web/venv/lib/python2.7/site-packages/flask/app.py", line 1982, in wsgi_app
    response = self.full_dispatch_request()
  File "/Users/olasteen/GoogleDrive/Kandidatprojekt/sentiment-web/venv/lib/python2.7/site-packages/flask/app.py", line 1614, in full_dispatch_request
    rv = self.handle_user_exception(e)
  File "/Users/olasteen/GoogleDrive/Kandidatprojekt/sentiment-web/venv/lib/python2.7/site-packages/flask/app.py", line 1517, in handle_user_exception
    reraise(exc_type, exc_value, tb)
  File "/Users/olasteen/GoogleDrive/Kandidatprojekt/sentiment-web/venv/lib/python2.7/site-packages/flask/app.py", line 1612, in full_dispatch_request
    rv = self.dispatch_request()
  File "/Users/olasteen/GoogleDrive/Kandidatprojekt/sentiment-web/venv/lib/python2.7/site-packages/flask/app.py", line 1598, in dispatch_request
    return self.view_functions[rule.endpoint](**req.view_args)
  File "/Users/olasteen/GoogleDrive/Kandidatprojekt/sentiment-web/server.py", line 32, in home
    conn.incr(STATS_KEY + "_hits")
  File "/Users/olasteen/GoogleDrive/Kandidatprojekt/sentiment-web/venv/lib/python2.7/site-packages/redis/client.py", line 915, in incr
    return self.execute_command('INCRBY', name, amount)
  File "/Users/olasteen/GoogleDrive/Kandidatprojekt/sentiment-web/venv/lib/python2.7/site-packages/redis/client.py", line 578, in execute_command
    connection.send_command(*args)
  File "/Users/olasteen/GoogleDrive/Kandidatprojekt/sentiment-web/venv/lib/python2.7/site-packages/redis/connection.py", line 563, in send_command
    self.send_packed_command(self.pack_command(*args))
  File "/Users/olasteen/GoogleDrive/Kandidatprojekt/sentiment-web/venv/lib/python2.7/site-packages/redis/connection.py", line 538, in send_packed_command
    self.connect()
  File "/Users/olasteen/GoogleDrive/Kandidatprojekt/sentiment-web/venv/lib/python2.7/site-packages/redis/connection.py", line 442, in connect
    raise ConnectionError(self._error_message(e))
ConnectionError: Error 61 connecting to :6379. Connection refused.
::1 - - [2017-02-28 13:37:15] "GET / HTTP/1.1" 500 412 0.003149
[2017-02-28 13:37:15,710] ERROR in app: Exception on / [GET]
Traceback (most recent call last):
  File "/Users/olasteen/GoogleDrive/Kandidatprojekt/sentiment-web/venv/lib/python2.7/site-packages/flask/app.py", line 1982, in wsgi_app
    response = self.full_dispatch_request()
  File "/Users/olasteen/GoogleDrive/Kandidatprojekt/sentiment-web/venv/lib/python2.7/site-packages/flask/app.py", line 1614, in full_dispatch_request
    rv = self.handle_user_exception(e)
  File "/Users/olasteen/GoogleDrive/Kandidatprojekt/sentiment-web/venv/lib/python2.7/site-packages/flask/app.py", line 1517, in handle_user_exception
    reraise(exc_type, exc_value, tb)
  File "/Users/olasteen/GoogleDrive/Kandidatprojekt/sentiment-web/venv/lib/python2.7/site-packages/flask/app.py", line 1612, in full_dispatch_request
    rv = self.dispatch_request()
  File "/Users/olasteen/GoogleDrive/Kandidatprojekt/sentiment-web/venv/lib/python2.7/site-packages/flask/app.py", line 1598, in dispatch_request
    return self.view_functions[rule.endpoint](**req.view_args)
  File "/Users/olasteen/GoogleDrive/Kandidatprojekt/sentiment-web/server.py", line 32, in home
    conn.incr(STATS_KEY + "_hits")
  File "/Users/olasteen/GoogleDrive/Kandidatprojekt/sentiment-web/venv/lib/python2.7/site-packages/redis/client.py", line 915, in incr
    return self.execute_command('INCRBY', name, amount)
  File "/Users/olasteen/GoogleDrive/Kandidatprojekt/sentiment-web/venv/lib/python2.7/site-packages/redis/client.py", line 578, in execute_command
    connection.send_command(*args)
  File "/Users/olasteen/GoogleDrive/Kandidatprojekt/sentiment-web/venv/lib/python2.7/site-packages/redis/connection.py", line 563, in send_command
    self.send_packed_command(self.pack_command(*args))
  File "/Users/olasteen/GoogleDrive/Kandidatprojekt/sentiment-web/venv/lib/python2.7/site-packages/redis/connection.py", line 538, in send_packed_command
    self.connect()
  File "/Users/olasteen/GoogleDrive/Kandidatprojekt/sentiment-web/venv/lib/python2.7/site-packages/redis/connection.py", line 442, in connect
    raise ConnectionError(self._error_message(e))
ConnectionError: Error 61 connecting to :6379. Connection refused.
::1 - - [2017-02-28 13:37:15] "GET / HTTP/1.1" 500 412 0.001782
[2017-02-28 13:37:15,895] ERROR in app: Exception on / [GET]
Traceback (most recent call last):
  File "/Users/olasteen/GoogleDrive/Kandidatprojekt/sentiment-web/venv/lib/python2.7/site-packages/flask/app.py", line 1982, in wsgi_app
    response = self.full_dispatch_request()
  File "/Users/olasteen/GoogleDrive/Kandidatprojekt/sentiment-web/venv/lib/python2.7/site-packages/flask/app.py", line 1614, in full_dispatch_request
    rv = self.handle_user_exception(e)
  File "/Users/olasteen/GoogleDrive/Kandidatprojekt/sentiment-web/venv/lib/python2.7/site-packages/flask/app.py", line 1517, in handle_user_exception
    reraise(exc_type, exc_value, tb)
  File "/Users/olasteen/GoogleDrive/Kandidatprojekt/sentiment-web/venv/lib/python2.7/site-packages/flask/app.py", line 1612, in full_dispatch_request
    rv = self.dispatch_request()
  File "/Users/olasteen/GoogleDrive/Kandidatprojekt/sentiment-web/venv/lib/python2.7/site-packages/flask/app.py", line 1598, in dispatch_request
    return self.view_functions[rule.endpoint](**req.view_args)
  File "/Users/olasteen/GoogleDrive/Kandidatprojekt/sentiment-web/server.py", line 32, in home
    conn.incr(STATS_KEY + "_hits")
  File "/Users/olasteen/GoogleDrive/Kandidatprojekt/sentiment-web/venv/lib/python2.7/site-packages/redis/client.py", line 915, in incr
    return self.execute_command('INCRBY', name, amount)
  File "/Users/olasteen/GoogleDrive/Kandidatprojekt/sentiment-web/venv/lib/python2.7/site-packages/redis/client.py", line 578, in execute_command
    connection.send_command(*args)
  File "/Users/olasteen/GoogleDrive/Kandidatprojekt/sentiment-web/venv/lib/python2.7/site-packages/redis/connection.py", line 563, in send_command
    self.send_packed_command(self.pack_command(*args))
  File "/Users/olasteen/GoogleDrive/Kandidatprojekt/sentiment-web/venv/lib/python2.7/site-packages/redis/connection.py", line 538, in send_packed_command
    self.connect()
  File "/Users/olasteen/GoogleDrive/Kandidatprojekt/sentiment-web/venv/lib/python2.7/site-packages/redis/connection.py", line 442, in connect
    raise ConnectionError(self._error_message(e))
ConnectionError: Error 61 connecting to :6379. Connection refused.
::1 - - [2017-02-28 13:37:15] "GET / HTTP/1.1" 500 412 0.001846
[2017-02-28 13:37:16,055] ERROR in app: Exception on / [GET]
Traceback (most recent call last):
  File "/Users/olasteen/GoogleDrive/Kandidatprojekt/sentiment-web/venv/lib/python2.7/site-packages/flask/app.py", line 1982, in wsgi_app
    response = self.full_dispatch_request()
  File "/Users/olasteen/GoogleDrive/Kandidatprojekt/sentiment-web/venv/lib/python2.7/site-packages/flask/app.py", line 1614, in full_dispatch_request
    rv = self.handle_user_exception(e)
  File "/Users/olasteen/GoogleDrive/Kandidatprojekt/sentiment-web/venv/lib/python2.7/site-packages/flask/app.py", line 1517, in handle_user_exception
    reraise(exc_type, exc_value, tb)
  File "/Users/olasteen/GoogleDrive/Kandidatprojekt/sentiment-web/venv/lib/python2.7/site-packages/flask/app.py", line 1612, in full_dispatch_request
    rv = self.dispatch_request()
  File "/Users/olasteen/GoogleDrive/Kandidatprojekt/sentiment-web/venv/lib/python2.7/site-packages/flask/app.py", line 1598, in dispatch_request
    return self.view_functions[rule.endpoint](**req.view_args)
  File "/Users/olasteen/GoogleDrive/Kandidatprojekt/sentiment-web/server.py", line 32, in home
    conn.incr(STATS_KEY + "_hits")
  File "/Users/olasteen/GoogleDrive/Kandidatprojekt/sentiment-web/venv/lib/python2.7/site-packages/redis/client.py", line 915, in incr
    return self.execute_command('INCRBY', name, amount)
  File "/Users/olasteen/GoogleDrive/Kandidatprojekt/sentiment-web/venv/lib/python2.7/site-packages/redis/client.py", line 578, in execute_command
    connection.send_command(*args)
  File "/Users/olasteen/GoogleDrive/Kandidatprojekt/sentiment-web/venv/lib/python2.7/site-packages/redis/connection.py", line 563, in send_command
    self.send_packed_command(self.pack_command(*args))
  File "/Users/olasteen/GoogleDrive/Kandidatprojekt/sentiment-web/venv/lib/python2.7/site-packages/redis/connection.py", line 538, in send_packed_command
    self.connect()
  File "/Users/olasteen/GoogleDrive/Kandidatprojekt/sentiment-web/venv/lib/python2.7/site-packages/redis/connection.py", line 442, in connect
    raise ConnectionError(self._error_message(e))
ConnectionError: Error 61 connecting to :6379. Connection refused.
::1 - - [2017-02-28 13:37:16] "GET / HTTP/1.1" 500 412 0.002416
[2017-02-28 13:37:16,204] ERROR in app: Exception on / [GET]
Traceback (most recent call last):
  File "/Users/olasteen/GoogleDrive/Kandidatprojekt/sentiment-web/venv/lib/python2.7/site-packages/flask/app.py", line 1982, in wsgi_app
    response = self.full_dispatch_request()
  File "/Users/olasteen/GoogleDrive/Kandidatprojekt/sentiment-web/venv/lib/python2.7/site-packages/flask/app.py", line 1614, in full_dispatch_request
    rv = self.handle_user_exception(e)
  File "/Users/olasteen/GoogleDrive/Kandidatprojekt/sentiment-web/venv/lib/python2.7/site-packages/flask/app.py", line 1517, in handle_user_exception
    reraise(exc_type, exc_value, tb)
  File "/Users/olasteen/GoogleDrive/Kandidatprojekt/sentiment-web/venv/lib/python2.7/site-packages/flask/app.py", line 1612, in full_dispatch_request
    rv = self.dispatch_request()
  File "/Users/olasteen/GoogleDrive/Kandidatprojekt/sentiment-web/venv/lib/python2.7/site-packages/flask/app.py", line 1598, in dispatch_request
    return self.view_functions[rule.endpoint](**req.view_args)
  File "/Users/olasteen/GoogleDrive/Kandidatprojekt/sentiment-web/server.py", line 32, in home
    conn.incr(STATS_KEY + "_hits")
  File "/Users/olasteen/GoogleDrive/Kandidatprojekt/sentiment-web/venv/lib/python2.7/site-packages/redis/client.py", line 915, in incr
    return self.execute_command('INCRBY', name, amount)
  File "/Users/olasteen/GoogleDrive/Kandidatprojekt/sentiment-web/venv/lib/python2.7/site-packages/redis/client.py", line 578, in execute_command
    connection.send_command(*args)
  File "/Users/olasteen/GoogleDrive/Kandidatprojekt/sentiment-web/venv/lib/python2.7/site-packages/redis/connection.py", line 563, in send_command
    self.send_packed_command(self.pack_command(*args))
  File "/Users/olasteen/GoogleDrive/Kandidatprojekt/sentiment-web/venv/lib/python2.7/site-packages/redis/connection.py", line 538, in send_packed_command
    self.connect()
  File "/Users/olasteen/GoogleDrive/Kandidatprojekt/sentiment-web/venv/lib/python2.7/site-packages/redis/connection.py", line 442, in connect
    raise ConnectionError(self._error_message(e))
ConnectionError: Error 61 connecting to :6379. Connection refused.
::1 - - [2017-02-28 13:37:16] "GET / HTTP/1.1" 500 412 0.001871
[2017-02-28 13:37:16,358] ERROR in app: Exception on / [GET]
Traceback (most recent call last):
  File "/Users/olasteen/GoogleDrive/Kandidatprojekt/sentiment-web/venv/lib/python2.7/site-packages/flask/app.py", line 1982, in wsgi_app
    response = self.full_dispatch_request()
  File "/Users/olasteen/GoogleDrive/Kandidatprojekt/sentiment-web/venv/lib/python2.7/site-packages/flask/app.py", line 1614, in full_dispatch_request
    rv = self.handle_user_exception(e)
  File "/Users/olasteen/GoogleDrive/Kandidatprojekt/sentiment-web/venv/lib/python2.7/site-packages/flask/app.py", line 1517, in handle_user_exception
    reraise(exc_type, exc_value, tb)
  File "/Users/olasteen/GoogleDrive/Kandidatprojekt/sentiment-web/venv/lib/python2.7/site-packages/flask/app.py", line 1612, in full_dispatch_request
    rv = self.dispatch_request()
  File "/Users/olasteen/GoogleDrive/Kandidatprojekt/sentiment-web/venv/lib/python2.7/site-packages/flask/app.py", line 1598, in dispatch_request
    return self.view_functions[rule.endpoint](**req.view_args)
  File "/Users/olasteen/GoogleDrive/Kandidatprojekt/sentiment-web/server.py", line 32, in home
    conn.incr(STATS_KEY + "_hits")
  File "/Users/olasteen/GoogleDrive/Kandidatprojekt/sentiment-web/venv/lib/python2.7/site-packages/redis/client.py", line 915, in incr
    return self.execute_command('INCRBY', name, amount)
  File "/Users/olasteen/GoogleDrive/Kandidatprojekt/sentiment-web/venv/lib/python2.7/site-packages/redis/client.py", line 578, in execute_command
    connection.send_command(*args)
  File "/Users/olasteen/GoogleDrive/Kandidatprojekt/sentiment-web/venv/lib/python2.7/site-packages/redis/connection.py", line 563, in send_command
    self.send_packed_command(self.pack_command(*args))
  File "/Users/olasteen/GoogleDrive/Kandidatprojekt/sentiment-web/venv/lib/python2.7/site-packages/redis/connection.py", line 538, in send_packed_command
    self.connect()
  File "/Users/olasteen/GoogleDrive/Kandidatprojekt/sentiment-web/venv/lib/python2.7/site-packages/redis/connection.py", line 442, in connect
    raise ConnectionError(self._error_message(e))
ConnectionError: Error 61 connecting to :6379. Connection refused.
::1 - - [2017-02-28 13:37:16] "GET / HTTP/1.1" 500 412 0.002512
[2017-02-28 13:37:16,474] ERROR in app: Exception on / [GET]
Traceback (most recent call last):
  File "/Users/olasteen/GoogleDrive/Kandidatprojekt/sentiment-web/venv/lib/python2.7/site-packages/flask/app.py", line 1982, in wsgi_app
    response = self.full_dispatch_request()
  File "/Users/olasteen/GoogleDrive/Kandidatprojekt/sentiment-web/venv/lib/python2.7/site-packages/flask/app.py", line 1614, in full_dispatch_request
    rv = self.handle_user_exception(e)
  File "/Users/olasteen/GoogleDrive/Kandidatprojekt/sentiment-web/venv/lib/python2.7/site-packages/flask/app.py", line 1517, in handle_user_exception
    reraise(exc_type, exc_value, tb)
  File "/Users/olasteen/GoogleDrive/Kandidatprojekt/sentiment-web/venv/lib/python2.7/site-packages/flask/app.py", line 1612, in full_dispatch_request
    rv = self.dispatch_request()
  File "/Users/olasteen/GoogleDrive/Kandidatprojekt/sentiment-web/venv/lib/python2.7/site-packages/flask/app.py", line 1598, in dispatch_request
    return self.view_functions[rule.endpoint](**req.view_args)
  File "/Users/olasteen/GoogleDrive/Kandidatprojekt/sentiment-web/server.py", line 32, in home
    conn.incr(STATS_KEY + "_hits")
  File "/Users/olasteen/GoogleDrive/Kandidatprojekt/sentiment-web/venv/lib/python2.7/site-packages/redis/client.py", line 915, in incr
    return self.execute_command('INCRBY', name, amount)
  File "/Users/olasteen/GoogleDrive/Kandidatprojekt/sentiment-web/venv/lib/python2.7/site-packages/redis/client.py", line 578, in execute_command
    connection.send_command(*args)
  File "/Users/olasteen/GoogleDrive/Kandidatprojekt/sentiment-web/venv/lib/python2.7/site-packages/redis/connection.py", line 563, in send_command
    self.send_packed_command(self.pack_command(*args))
  File "/Users/olasteen/GoogleDrive/Kandidatprojekt/sentiment-web/venv/lib/python2.7/site-packages/redis/connection.py", line 538, in send_packed_command
    self.connect()
  File "/Users/olasteen/GoogleDrive/Kandidatprojekt/sentiment-web/venv/lib/python2.7/site-packages/redis/connection.py", line 442, in connect
    raise ConnectionError(self._error_message(e))
ConnectionError: Error 61 connecting to :6379. Connection refused.
::1 - - [2017-02-28 13:37:16] "GET / HTTP/1.1" 500 412 0.002756
[2017-02-28 13:37:16,640] ERROR in app: Exception on / [GET]
Traceback (most recent call last):
  File "/Users/olasteen/GoogleDrive/Kandidatprojekt/sentiment-web/venv/lib/python2.7/site-packages/flask/app.py", line 1982, in wsgi_app
    response = self.full_dispatch_request()
  File "/Users/olasteen/GoogleDrive/Kandidatprojekt/sentiment-web/venv/lib/python2.7/site-packages/flask/app.py", line 1614, in full_dispatch_request
    rv = self.handle_user_exception(e)
  File "/Users/olasteen/GoogleDrive/Kandidatprojekt/sentiment-web/venv/lib/python2.7/site-packages/flask/app.py", line 1517, in handle_user_exception
    reraise(exc_type, exc_value, tb)
  File "/Users/olasteen/GoogleDrive/Kandidatprojekt/sentiment-web/venv/lib/python2.7/site-packages/flask/app.py", line 1612, in full_dispatch_request
    rv = self.dispatch_request()
  File "/Users/olasteen/GoogleDrive/Kandidatprojekt/sentiment-web/venv/lib/python2.7/site-packages/flask/app.py", line 1598, in dispatch_request
    return self.view_functions[rule.endpoint](**req.view_args)
  File "/Users/olasteen/GoogleDrive/Kandidatprojekt/sentiment-web/server.py", line 32, in home
    conn.incr(STATS_KEY + "_hits")
  File "/Users/olasteen/GoogleDrive/Kandidatprojekt/sentiment-web/venv/lib/python2.7/site-packages/redis/client.py", line 915, in incr
    return self.execute_command('INCRBY', name, amount)
  File "/Users/olasteen/GoogleDrive/Kandidatprojekt/sentiment-web/venv/lib/python2.7/site-packages/redis/client.py", line 578, in execute_command
    connection.send_command(*args)
  File "/Users/olasteen/GoogleDrive/Kandidatprojekt/sentiment-web/venv/lib/python2.7/site-packages/redis/connection.py", line 563, in send_command
    self.send_packed_command(self.pack_command(*args))
  File "/Users/olasteen/GoogleDrive/Kandidatprojekt/sentiment-web/venv/lib/python2.7/site-packages/redis/connection.py", line 538, in send_packed_command
    self.connect()
  File "/Users/olasteen/GoogleDrive/Kandidatprojekt/sentiment-web/venv/lib/python2.7/site-packages/redis/connection.py", line 442, in connect
    raise ConnectionError(self._error_message(e))
ConnectionError: Error 61 connecting to :6379. Connection refused.
::1 - - [2017-02-28 13:37:16] "GET / HTTP/1.1" 500 412 0.001562
Traceback (most recent call last):
  File "run.py", line 9, in <module>
    http_server.serve_forever()
  File "/Users/olasteen/GoogleDrive/Kandidatprojekt/sentiment-web/venv/lib/python2.7/site-packages/gevent/baseserver.py", line 360, in serve_forever
    self.start()
  File "/Users/olasteen/GoogleDrive/Kandidatprojekt/sentiment-web/venv/lib/python2.7/site-packages/gevent/baseserver.py", line 304, in start
    self.init_socket()
  File "/Users/olasteen/GoogleDrive/Kandidatprojekt/sentiment-web/venv/lib/python2.7/site-packages/gevent/pywsgi.py", line 1451, in init_socket
    StreamServer.init_socket(self)
  File "/Users/olasteen/GoogleDrive/Kandidatprojekt/sentiment-web/venv/lib/python2.7/site-packages/gevent/server.py", line 127, in init_socket
    self.socket = self.get_listener(self.address, self.backlog, self.family)
  File "/Users/olasteen/GoogleDrive/Kandidatprojekt/sentiment-web/venv/lib/python2.7/site-packages/gevent/server.py", line 138, in get_listener
    return _tcp_listener(address, backlog=backlog, reuse_addr=cls.reuse_addr, family=family)
  File "/Users/olasteen/GoogleDrive/Kandidatprojekt/sentiment-web/venv/lib/python2.7/site-packages/gevent/server.py", line 228, in _tcp_listener
    sock.bind(address)
  File "<string>", line 1, in bind
socket.error: [Errno 48] Address already in use: ('', 5037)
[2017-02-28 13:46:07,648] ERROR in app: Exception on / [GET]
Traceback (most recent call last):
  File "/Users/olasteen/GoogleDrive/Kandidatprojekt/sentiment-web/venv/lib/python2.7/site-packages/flask/app.py", line 1982, in wsgi_app
    response = self.full_dispatch_request()
  File "/Users/olasteen/GoogleDrive/Kandidatprojekt/sentiment-web/venv/lib/python2.7/site-packages/flask/app.py", line 1614, in full_dispatch_request
    rv = self.handle_user_exception(e)
  File "/Users/olasteen/GoogleDrive/Kandidatprojekt/sentiment-web/venv/lib/python2.7/site-packages/flask/app.py", line 1517, in handle_user_exception
    reraise(exc_type, exc_value, tb)
  File "/Users/olasteen/GoogleDrive/Kandidatprojekt/sentiment-web/venv/lib/python2.7/site-packages/flask/app.py", line 1612, in full_dispatch_request
    rv = self.dispatch_request()
  File "/Users/olasteen/GoogleDrive/Kandidatprojekt/sentiment-web/venv/lib/python2.7/site-packages/flask/app.py", line 1598, in dispatch_request
    return self.view_functions[rule.endpoint](**req.view_args)
  File "/Users/olasteen/GoogleDrive/Kandidatprojekt/sentiment-web/server.py", line 32, in home
    conn.incr(STATS_KEY + "_hits")
  File "/Users/olasteen/GoogleDrive/Kandidatprojekt/sentiment-web/venv/lib/python2.7/site-packages/redis/client.py", line 915, in incr
    return self.execute_command('INCRBY', name, amount)
  File "/Users/olasteen/GoogleDrive/Kandidatprojekt/sentiment-web/venv/lib/python2.7/site-packages/redis/client.py", line 578, in execute_command
    connection.send_command(*args)
  File "/Users/olasteen/GoogleDrive/Kandidatprojekt/sentiment-web/venv/lib/python2.7/site-packages/redis/connection.py", line 563, in send_command
    self.send_packed_command(self.pack_command(*args))
  File "/Users/olasteen/GoogleDrive/Kandidatprojekt/sentiment-web/venv/lib/python2.7/site-packages/redis/connection.py", line 538, in send_packed_command
    self.connect()
  File "/Users/olasteen/GoogleDrive/Kandidatprojekt/sentiment-web/venv/lib/python2.7/site-packages/redis/connection.py", line 442, in connect
    raise ConnectionError(self._error_message(e))
ConnectionError: Error 61 connecting to :6379. Connection refused.
::1 - - [2017-02-28 13:46:07] "GET / HTTP/1.1" 500 412 0.002346
Traceback (most recent call last):
  File "run.py", line 9, in <module>
    http_server.serve_forever()
  File "/Users/olasteen/GoogleDrive/Kandidatprojekt/sentiment-web/venv/lib/python2.7/site-packages/gevent/baseserver.py", line 360, in serve_forever
    self.start()
  File "/Users/olasteen/GoogleDrive/Kandidatprojekt/sentiment-web/venv/lib/python2.7/site-packages/gevent/baseserver.py", line 304, in start
    self.init_socket()
  File "/Users/olasteen/GoogleDrive/Kandidatprojekt/sentiment-web/venv/lib/python2.7/site-packages/gevent/pywsgi.py", line 1451, in init_socket
    StreamServer.init_socket(self)
  File "/Users/olasteen/GoogleDrive/Kandidatprojekt/sentiment-web/venv/lib/python2.7/site-packages/gevent/server.py", line 127, in init_socket
    self.socket = self.get_listener(self.address, self.backlog, self.family)
  File "/Users/olasteen/GoogleDrive/Kandidatprojekt/sentiment-web/venv/lib/python2.7/site-packages/gevent/server.py", line 138, in get_listener
    return _tcp_listener(address, backlog=backlog, reuse_addr=cls.reuse_addr, family=family)
  File "/Users/olasteen/GoogleDrive/Kandidatprojekt/sentiment-web/venv/lib/python2.7/site-packages/gevent/server.py", line 228, in _tcp_listener
    sock.bind(address)
  File "<string>", line 1, in bind
socket.error: [Errno 48] Address already in use: ('', 5037)
[2017-02-28 13:52:02,620] ERROR in app: Exception on / [GET]
Traceback (most recent call last):
  File "/Users/olasteen/GoogleDrive/Kandidatprojekt/sentiment-web/venv/lib/python2.7/site-packages/flask/app.py", line 1982, in wsgi_app
    response = self.full_dispatch_request()
  File "/Users/olasteen/GoogleDrive/Kandidatprojekt/sentiment-web/venv/lib/python2.7/site-packages/flask/app.py", line 1614, in full_dispatch_request
    rv = self.handle_user_exception(e)
  File "/Users/olasteen/GoogleDrive/Kandidatprojekt/sentiment-web/venv/lib/python2.7/site-packages/flask/app.py", line 1517, in handle_user_exception
    reraise(exc_type, exc_value, tb)
  File "/Users/olasteen/GoogleDrive/Kandidatprojekt/sentiment-web/venv/lib/python2.7/site-packages/flask/app.py", line 1612, in full_dispatch_request
    rv = self.dispatch_request()
  File "/Users/olasteen/GoogleDrive/Kandidatprojekt/sentiment-web/venv/lib/python2.7/site-packages/flask/app.py", line 1598, in dispatch_request
    return self.view_functions[rule.endpoint](**req.view_args)
  File "/Users/olasteen/GoogleDrive/Kandidatprojekt/sentiment-web/server.py", line 32, in home
    return render_template("index.html")
  File "/Users/olasteen/GoogleDrive/Kandidatprojekt/sentiment-web/venv/lib/python2.7/site-packages/redis/client.py", line 915, in incr
    return self.execute_command('INCRBY', name, amount)
  File "/Users/olasteen/GoogleDrive/Kandidatprojekt/sentiment-web/venv/lib/python2.7/site-packages/redis/client.py", line 578, in execute_command
    connection.send_command(*args)
  File "/Users/olasteen/GoogleDrive/Kandidatprojekt/sentiment-web/venv/lib/python2.7/site-packages/redis/connection.py", line 563, in send_command
    self.send_packed_command(self.pack_command(*args))
  File "/Users/olasteen/GoogleDrive/Kandidatprojekt/sentiment-web/venv/lib/python2.7/site-packages/redis/connection.py", line 538, in send_packed_command
    self.connect()
  File "/Users/olasteen/GoogleDrive/Kandidatprojekt/sentiment-web/venv/lib/python2.7/site-packages/redis/connection.py", line 442, in connect
    raise ConnectionError(self._error_message(e))
ConnectionError: Error 61 connecting to :6379. Connection refused.
::1 - - [2017-02-28 13:52:02] "GET / HTTP/1.1" 500 412 0.002849
[2017-02-28 13:52:09,547] ERROR in app: Exception on / [GET]
Traceback (most recent call last):
  File "/Users/olasteen/GoogleDrive/Kandidatprojekt/sentiment-web/venv/lib/python2.7/site-packages/flask/app.py", line 1982, in wsgi_app
    response = self.full_dispatch_request()
  File "/Users/olasteen/GoogleDrive/Kandidatprojekt/sentiment-web/venv/lib/python2.7/site-packages/flask/app.py", line 1614, in full_dispatch_request
    rv = self.handle_user_exception(e)
  File "/Users/olasteen/GoogleDrive/Kandidatprojekt/sentiment-web/venv/lib/python2.7/site-packages/flask/app.py", line 1517, in handle_user_exception
    reraise(exc_type, exc_value, tb)
  File "/Users/olasteen/GoogleDrive/Kandidatprojekt/sentiment-web/venv/lib/python2.7/site-packages/flask/app.py", line 1612, in full_dispatch_request
    rv = self.dispatch_request()
  File "/Users/olasteen/GoogleDrive/Kandidatprojekt/sentiment-web/venv/lib/python2.7/site-packages/flask/app.py", line 1598, in dispatch_request
    return self.view_functions[rule.endpoint](**req.view_args)
  File "/Users/olasteen/GoogleDrive/Kandidatprojekt/sentiment-web/server.py", line 31, in home
    conn.incr(STATS_KEY + "_hits")
NameError: global name 'conn' is not defined
::1 - - [2017-02-28 13:52:09] "GET / HTTP/1.1" 500 412 0.011727
::1 - - [2017-02-28 13:52:09] "GET /favicon.ico HTTP/1.1" 404 342 0.015922
[2017-02-28 14:01:20,281] ERROR in app: Exception on / [GET]
Traceback (most recent call last):
  File "/Users/olasteen/GoogleDrive/Kandidatprojekt/sentiment-web/venv/lib/python2.7/site-packages/flask/app.py", line 1982, in wsgi_app
    response = self.full_dispatch_request()
  File "/Users/olasteen/GoogleDrive/Kandidatprojekt/sentiment-web/venv/lib/python2.7/site-packages/flask/app.py", line 1614, in full_dispatch_request
    rv = self.handle_user_exception(e)
  File "/Users/olasteen/GoogleDrive/Kandidatprojekt/sentiment-web/venv/lib/python2.7/site-packages/flask/app.py", line 1517, in handle_user_exception
    reraise(exc_type, exc_value, tb)
  File "/Users/olasteen/GoogleDrive/Kandidatprojekt/sentiment-web/venv/lib/python2.7/site-packages/flask/app.py", line 1612, in full_dispatch_request
    rv = self.dispatch_request()
  File "/Users/olasteen/GoogleDrive/Kandidatprojekt/sentiment-web/venv/lib/python2.7/site-packages/flask/app.py", line 1598, in dispatch_request
    return self.view_functions[rule.endpoint](**req.view_args)
  File "/Users/olasteen/GoogleDrive/Kandidatprojekt/sentiment-web/server.py", line 31, in home
    conn.incr(STATS_KEY + "_hits")
NameError: global name 'conn' is not defined
::1 - - [2017-02-28 14:01:20] "GET / HTTP/1.1" 500 412 0.019381
::1 - - [2017-02-28 14:15:57] "GET / HTTP/1.1" 200 2791 0.023118
::1 - - [2017-02-28 14:15:57] "GET /static/css/bootstrap.min.css HTTP/1.1" 200 97620 0.018847
::1 - - [2017-02-28 14:15:57] "GET /static/css/styles.css HTTP/1.1" 200 330 0.003332
::1 - - [2017-02-28 14:15:57] "GET /static/underscore-min.js HTTP/1.1" 200 14637 0.004248
::1 - - [2017-02-28 14:15:57] "GET /static/app.js HTTP/1.1" 200 614 0.002017
::1 - - [2017-02-28 14:16:04] "POST /web/text/ HTTP/1.1" 200 279 0.013915
::1 - - [2017-02-28 14:23:39] "GET / HTTP/1.1" 200 2791 0.028978
::1 - - [2017-02-28 14:23:59] "POST /web/text/ HTTP/1.1" 200 287 0.002945
::1 - - [2017-02-28 14:24:06] "POST /web/text/ HTTP/1.1" 200 287 0.001094
::1 - - [2017-02-28 14:24:09] "POST /web/text/ HTTP/1.1" 200 287 0.002026
::1 - - [2017-02-28 14:24:13] "POST /web/text/ HTTP/1.1" 200 268 0.001131
::1 - - [2017-02-28 14:24:22] "POST /web/text/ HTTP/1.1" 200 277 0.002250
::1 - - [2017-02-28 14:24:28] "POST /web/text/ HTTP/1.1" 200 278 0.002127
::1 - - [2017-02-28 14:24:29] "POST /web/text/ HTTP/1.1" 200 278 0.001012
::1 - - [2017-02-28 14:26:00] "GET / HTTP/1.1" 200 2791 0.001552
::1 - - [2017-02-28 14:26:15] "GET / HTTP/1.1" 200 2791 0.001613
::1 - - [2017-03-01 08:57:24] "GET / HTTP/1.1" 200 2791 0.016780
::1 - - [2017-03-01 08:57:24] "GET /static/app.js HTTP/1.1" 200 614 0.012195
::1 - - [2017-03-01 08:57:24] "GET /static/css/bootstrap.min.css HTTP/1.1" 304 183 0.001374
::1 - - [2017-03-01 08:57:24] "GET /static/css/styles.css HTTP/1.1" 304 180 0.001170
::1 - - [2017-03-01 08:57:24] "GET /static/underscore-min.js HTTP/1.1" 304 182 0.000870
